<mujoco model="arm3d">
	<compiler angle="radian" coordinate="local" inertiafromgeom="true"/>
	<option gravity="0 0 0" integrator="Euler" timestep="0.01" iterations="20"/>
	<default >
		<joint damping="1" limited="true" armature="0.04"/>
		<geom friction="0.8 0.1 0.1" contype="0" condim="1" margin="0.002" conaffinity="0" density="300"/>
	</default>
	<worldbody >
		<light diffuse=".5 .5 .5" dir="0 0 -1" pos="0 0 3"/>
		<geom name="table" pos="0 0.5 -0.325" contype="1" type="plane" conaffinity="1" size="1 1 0.1" material="table"/>
		<body name="r_shoulder_pan_link" pos="0 -0.6 0">
			<geom pos="-0.06 0.05 0.2" name="e1" type="sphere" size="0.05" rgba="0.6 0.6 0.6 1"/>
			<geom pos=" 0.06 0.05 0.2" name="e2" type="sphere" size="0.05" rgba="0.6 0.6 0.6 1"/>
			<geom pos="-0.06 0.09 0.2" name="e1p" type="sphere" size="0.03" rgba="0.1 0.1 0.1 1"/>
			<geom pos=" 0.06 0.09 0.2" name="e2p" type="sphere" size="0.03" rgba="0.1 0.1 0.1 1"/>
			<geom name="sp" type="capsule" size="0.1" fromto="0 0 -0.4 0 0 0.2"/>
			<joint name="r_shoulder_pan_joint" damping="1.0" pos="0 0 0" range="-2.2854 1.714602" axis="0 0 1" type="hinge"/>
			<body name="r_shoulder_lift_link" pos="0.1 0 0">
				<geom name="sl" type="capsule" size="0.1" fromto="0 -0.1 0 0 0.1 0"/>
				<joint name="r_shoulder_lift_joint" damping="1.0" pos="0 0 0" range="-0.5236 1.3963" axis="0 1 0" type="hinge"/>
				<body name="r_upper_arm_roll_link" pos="0 0 0">
					<geom name="uar" type="capsule" size="0.02" fromto="-0.1 0 0 0.1 0 0"/>
					<joint name="r_upper_arm_roll_joint" damping="0.1" pos="0 0 0" range="-1.5 1.7" axis="1 0 0" type="hinge"/>
					<body name="r_upper_arm_link" pos="0 0 0">
						<geom name="ua" type="capsule" size="0.06" fromto="0 0 0 0.4 0 0"/>
						<body name="r_elbow_flex_link" pos="0.4 0 0">
							<geom name="ef" type="capsule" size="0.06" fromto="0 -0.02 0 0.0 0.02 0"/>
							<joint name="r_elbow_flex_joint" damping="0.1" pos="0 0 0" range="-2.3213 0" axis="0 1 0" type="hinge"/>
							<body name="r_forearm_roll_link" pos="0 0 0">
								<geom name="fr" type="capsule" size="0.02" fromto="-0.1 0 0 0.1 0 0"/>
								<joint name="r_forearm_roll_joint" damping=".1" pos="0 0 0" range="-1.5 1.5" axis="1 0 0" type="hinge" limited="true"/>
								<body name="r_forearm_link" pos="0 0 0">
									<geom name="fa" type="capsule" size="0.05" fromto="0 0 0 0.291 0 0"/>
									<body name="r_wrist_flex_link" pos="0.321 0 0">
										<geom name="wf" type="capsule" size="0.01" fromto="0 -0.02 0 0 0.02 0"/>
										<joint name="r_wrist_flex_joint" damping=".1" pos="0 0 0" range="-1.094 0" axis="0 1 0" type="hinge"/>
										<body name="r_wrist_roll_link" pos="0 0 0">
											<joint name="r_wrist_roll_joint" damping="0.1" pos="0 0 0" range="-1.5 1.5" axis="1 0 0" type="hinge" limited="true"/>
											<body name="tips_arm" pos="0 0 0">
												<geom name="tip_arml" type="sphere" pos="0.1 -0.1 0." size="0.01"/>
												<geom name="tip_armr" type="sphere" pos="0.1 0.1 0." size="0.01"/>
											</body>
											<geom type="capsule" conaffinity="1" size="0.02" contype="1" fromto="0 -0.1 0. 0.0 +0.1 0"/>
											<geom type="capsule" conaffinity="1" size="0.02" contype="1" fromto="0 -0.1 0. 0.1 -0.1 0"/>
											<geom type="capsule" conaffinity="1" size="0.02" contype="1" fromto="0 +0.1 0. 0.1 +0.1 0"/>
										</body>
									</body>
								</body>
							</body>
						</body>
					</body>
				</body>
			</body>
		</body>
		<body name="distractor" pos="0.477720160797 -0.0389180516334 -0.358581564995">
			<geom mesh="distractor_mesh" contype="1" type="mesh" conaffinity="0" material="distractor" density="2748.85933274" rgba="1 1 1 1"/>
			<joint name="distractor_slidey" damping="1.598100985211206" pos="0 0 0" range="-10.3213 10.3" axis="0 1 0" type="slide"/>
			<joint name="distractor_slidex" damping="1.598100985211206" pos="0 0 0" range="-10.3213 10.3" axis="1 0 0" type="slide"/>
		</body>
		<body name="object" pos="0.446479957092 -0.049967793988 -0.324">
			<geom mesh="object_mesh" contype="1" type="mesh" conaffinity="0" material="object" density="1314.40942651" rgba="1 1 1 1"/>
			<joint name="obj_slidey" damping="2.835673098817997" pos="0 0 0" range="-10.3213 10.3" axis="0 1 0" type="slide"/>
			<joint name="obj_slidex" damping="2.835673098817997" pos="0 0 0" range="-10.3213 10.3" axis="1 0 0" type="slide"/>
		</body>
		<body name="goal" pos="0.45 -0.05 -0.323">
			<geom contype="0" type="cylinder" conaffinity="0" rgba="1 0 0 1" density="0.00001" size="0.08 0.001 0.1"/>
			<joint name="goal_slidey" damping="0.5" pos="0 0 0" range="-10.3213 10.3" axis="0 1 0" type="slide"/>
			<joint name="goal_slidex" damping="0.5" pos="0 0 0" range="-10.3213 10.3" axis="1 0 0" type="slide"/>
		</body>
	</worldbody>
	<asset >
		<texture name="table" type="2d" file="/home/cfinn/code/rllab/vendor/textures/table_textures/wpic_002.png"/>
		<material specular="1" name="table" texture="table" shininess="0.3" rgba="0.9 0.9 0.9 1"/>
		<mesh scale="0.00102921038777 0.00102921038777 0.00102921038777" name="object_mesh" file="/home/cfinn/code/rllab/vendor/mujoco_models/vase1.stl"/>
		<mesh scale="0.000448338987875 0.000448338987875 0.000448338987875" name="distractor_mesh" file="/home/cfinn/code/rllab/vendor/mujoco_models/1960_corvette.stl"/>
		<texture name="distractor" file="/home/cfinn/code/rllab/vendor/textures/obj_textures/knitted_0076.png"/>
		<material specular="1" name="distractor" texture="distractor" shininess="0.3" rgba="0.9 0.9 0.9 1"/>
		<texture name="object" file="/home/cfinn/code/rllab/vendor/textures/obj_textures/knitted_0079.png"/>
		<material specular="1" name="object" texture="object" shininess="0.3" rgba="0.9 0.9 0.9 1"/>
	</asset>
	<actuator >
		<motor ctrllimited="true" joint="r_shoulder_pan_joint" ctrlrange="-2.0 2.0"/>
		<motor ctrllimited="true" joint="r_shoulder_lift_joint" ctrlrange="-2.0 2.0"/>
		<motor ctrllimited="true" joint="r_upper_arm_roll_joint" ctrlrange="-2.0 2.0"/>
		<motor ctrllimited="true" joint="r_elbow_flex_joint" ctrlrange="-2.0 2.0"/>
		<motor ctrllimited="true" joint="r_forearm_roll_joint" ctrlrange="-2.0 2.0"/>
		<motor ctrllimited="true" joint="r_wrist_flex_joint" ctrlrange="-2.0 2.0"/>
		<motor ctrllimited="true" joint="r_wrist_roll_joint" ctrlrange="-2.0 2.0"/>
	</actuator>
</mujoco>
